2021-06-29 13:30:58,608 ERROR: Exception on /favicon.ico [GET] [in /home/nicolas/2bij3/venv/lib/python3.8/site-packages/flask/app.py:1454]
Traceback (most recent call last):
  File "/home/nicolas/2bij3/venv/lib/python3.8/site-packages/flask/app.py", line 1513, in full_dispatch_request
    rv = self.dispatch_request()
  File "/home/nicolas/2bij3/venv/lib/python3.8/site-packages/flask/app.py", line 1489, in dispatch_request
    self.raise_routing_exception(req)
  File "/home/nicolas/2bij3/venv/lib/python3.8/site-packages/flask/app.py", line 1471, in raise_routing_exception
    raise request.routing_exception  # type: ignore
  File "/home/nicolas/2bij3/venv/lib/python3.8/site-packages/flask/ctx.py", line 367, in match_request
    result = self.url_adapter.match(return_rule=True)  # type: ignore
  File "/home/nicolas/2bij3/venv/lib/python3.8/site-packages/werkzeug/routing.py", line 2032, in match
    raise NotFound()
werkzeug.exceptions.NotFound: 404 Not Found: The requested URL was not found on the server. If you entered the URL manually please check your spelling and try again.

During handling of the above exception, another exception occurred:

Traceback (most recent call last):
  File "/home/nicolas/2bij3/venv/lib/python3.8/site-packages/sqlalchemy/engine/base.py", line 1276, in _execute_context
    self.dialect.do_execute(
  File "/home/nicolas/2bij3/venv/lib/python3.8/site-packages/sqlalchemy/engine/default.py", line 608, in do_execute
    cursor.execute(statement, parameters)
sqlite3.OperationalError: no such table: user

The above exception was the direct cause of the following exception:

Traceback (most recent call last):
  File "/home/nicolas/2bij3/venv/lib/python3.8/site-packages/flask/app.py", line 2070, in wsgi_app
    response = self.full_dispatch_request()
  File "/home/nicolas/2bij3/venv/lib/python3.8/site-packages/flask/app.py", line 1515, in full_dispatch_request
    rv = self.handle_user_exception(e)
  File "/home/nicolas/2bij3/venv/lib/python3.8/site-packages/flask/app.py", line 1383, in handle_user_exception
    return self.handle_http_exception(e)
  File "/home/nicolas/2bij3/venv/lib/python3.8/site-packages/flask/app.py", line 1323, in handle_http_exception
    return self.ensure_sync(handler)(e)
  File "/home/nicolas/2bij3/app/errors.py", line 6, in not_found_error
    return render_template('404.html')
  File "/home/nicolas/2bij3/venv/lib/python3.8/site-packages/flask/templating.py", line 146, in render_template
    ctx.app.update_template_context(context)
  File "/home/nicolas/2bij3/venv/lib/python3.8/site-packages/flask/app.py", line 756, in update_template_context
    context.update(func())
  File "/home/nicolas/2bij3/venv/lib/python3.8/site-packages/flask_login/utils.py", line 379, in _user_context_processor
    return dict(current_user=_get_user())
  File "/home/nicolas/2bij3/venv/lib/python3.8/site-packages/flask_login/utils.py", line 346, in _get_user
    current_app.login_manager._load_user()
  File "/home/nicolas/2bij3/venv/lib/python3.8/site-packages/flask_login/login_manager.py", line 318, in _load_user
    user = self._user_callback(user_id)
  File "/home/nicolas/2bij3/app/models.py", line 177, in load_user
    return User.query.get(int(id))
  File "/home/nicolas/2bij3/venv/lib/python3.8/site-packages/sqlalchemy/orm/query.py", line 1018, in get
    return self._get_impl(ident, loading.load_on_pk_identity)
  File "/home/nicolas/2bij3/venv/lib/python3.8/site-packages/sqlalchemy/orm/query.py", line 1135, in _get_impl
    return db_load_fn(self, primary_key_identity)
  File "/home/nicolas/2bij3/venv/lib/python3.8/site-packages/sqlalchemy/orm/loading.py", line 286, in load_on_pk_identity
    return q.one()
  File "/home/nicolas/2bij3/venv/lib/python3.8/site-packages/sqlalchemy/orm/query.py", line 3490, in one
    ret = self.one_or_none()
  File "/home/nicolas/2bij3/venv/lib/python3.8/site-packages/sqlalchemy/orm/query.py", line 3459, in one_or_none
    ret = list(self)
  File "/home/nicolas/2bij3/venv/lib/python3.8/site-packages/sqlalchemy/orm/query.py", line 3535, in __iter__
    return self._execute_and_instances(context)
  File "/home/nicolas/2bij3/venv/lib/python3.8/site-packages/sqlalchemy/orm/query.py", line 3560, in _execute_and_instances
    result = conn.execute(querycontext.statement, self._params)
  File "/home/nicolas/2bij3/venv/lib/python3.8/site-packages/sqlalchemy/engine/base.py", line 1011, in execute
    return meth(self, multiparams, params)
  File "/home/nicolas/2bij3/venv/lib/python3.8/site-packages/sqlalchemy/sql/elements.py", line 298, in _execute_on_connection
    return connection._execute_clauseelement(self, multiparams, params)
  File "/home/nicolas/2bij3/venv/lib/python3.8/site-packages/sqlalchemy/engine/base.py", line 1124, in _execute_clauseelement
    ret = self._execute_context(
  File "/home/nicolas/2bij3/venv/lib/python3.8/site-packages/sqlalchemy/engine/base.py", line 1316, in _execute_context
    self._handle_dbapi_exception(
  File "/home/nicolas/2bij3/venv/lib/python3.8/site-packages/sqlalchemy/engine/base.py", line 1510, in _handle_dbapi_exception
    util.raise_(
  File "/home/nicolas/2bij3/venv/lib/python3.8/site-packages/sqlalchemy/util/compat.py", line 182, in raise_
    raise exception
  File "/home/nicolas/2bij3/venv/lib/python3.8/site-packages/sqlalchemy/engine/base.py", line 1276, in _execute_context
    self.dialect.do_execute(
  File "/home/nicolas/2bij3/venv/lib/python3.8/site-packages/sqlalchemy/engine/default.py", line 608, in do_execute
    cursor.execute(statement, parameters)
sqlalchemy.exc.OperationalError: (sqlite3.OperationalError) no such table: user
[SQL: SELECT user.id AS user_id, user.username AS user_username, user.password_hash AS user_password_hash, user.email_hash AS user_email_hash, user.email_contact AS user_email_contact, user."group" AS user_group, user.first_login AS user_first_login, user.last_visit AS user_last_visit, user.phase_completed AS user_phase_completed, user.fake AS user_fake, user.panel_id AS user_panel_id, user.activated AS user_activated, user.reminder_sent AS user_reminder_sent, user.sum_logins AS user_sum_logins, user.sum_ratings AS user_sum_ratings, user.sum_invites AS user_sum_invites, user.sum_stories AS user_sum_stories 
FROM user 
WHERE user.id = ?]
[parameters: (1,)]
(Background on this error at: http://sqlalche.me/e/13/e3q8)
2021-06-29 13:31:16,991 INFO: 3bij3 startup [in /home/nicolas/2bij3/app/__init__.py:75]
2021-06-29 13:31:24,212 INFO: 3bij3 startup [in /home/nicolas/2bij3/app/__init__.py:75]
2021-06-29 13:31:32,583 INFO: 3bij3 startup [in /home/nicolas/2bij3/app/__init__.py:75]
2021-06-29 13:31:41,631 INFO: 3bij3 startup [in /home/nicolas/2bij3/app/__init__.py:75]
2021-06-29 13:59:54,673 INFO: 3bij3 startup [in /home/nicolas/2bij3/app/__init__.py:75]
2021-06-29 14:06:48,182 INFO: 3bij3 startup [in /home/nicolas/2bij3/app/__init__.py:75]
2021-06-29 14:08:11,487 INFO: 3bij3 startup [in /home/nicolas/2bij3/app/__init__.py:75]
2021-06-29 14:10:10,251 INFO: 3bij3 startup [in /home/nicolas/2bij3/app/__init__.py:75]
2021-06-29 14:12:03,394 INFO: 3bij3 startup [in /home/nicolas/2bij3/app/__init__.py:75]
2021-06-29 14:13:32,560 INFO: 3bij3 startup [in /home/nicolas/2bij3/app/__init__.py:75]
2021-06-29 14:16:30,034 INFO: 3bij3 startup [in /home/nicolas/2bij3/app/__init__.py:75]
2021-06-29 14:17:50,020 INFO: 3bij3 startup [in /home/nicolas/2bij3/app/__init__.py:75]
2021-06-29 14:21:48,990 INFO: 3bij3 startup [in /home/nicolas/2bij3/app/__init__.py:75]
